Workbook
Name CECOS: 'DETALLE ENERGIA Y FACTURA'!$A$1:$AD$44

Sheet DETALLE ENERGIA Y FACTURA
A1: NUMERO CECOS | B1: CECOS | C1: AREAS | D1: SUB AREAS | E1: 44197 | F1: 44228 | G1: 44256 | H1: 44287 | I1: 44317 | J1: 44348 | K1: 44378 | L1: 44409 | M1: 44440 | N1: 44470 | O1: 44501 | P1: 44531 | Q1: TOTAL-21 | R1: 44562 | S1: 44593 | T1: 44621 | U1: 44652 | V1: 44682 | W1: 44713 | X1: 44743 | Y1: 44774 | Z1: 44805 | AA1: 44835 | AB1: 44866 | AC1: 44896 | AD1: TOTAL-22 | AE1: 44927 | AF1: 44958 | AG1: 44986 | AH1: 45017 | AI1: 45047 | AJ1: 45078 | AK1: 45108 | AL1: 45139 | AM1: 45170 | AN1: 45200 | AO1: 45231 | AP1: 45261 | AQ1: TOTAL-23 | AR1: 45292 | AS1: 45323 | AT1: 45352 | AU1: 45383 | AV1: 45413 | AW1: 45444 | AX1: 45474 | AY1: 45505 | AZ1: 45536 | BA1: 45566 | BB1: 45597 | BC1: 45627 | BD1: TOTAL-24 | BE1: 45658 | BF1: 45689 | BG1: 45717 | BH1: 45748 | BI1: 45778 | BJ1: 45809 | BK1: 45839 | BL1: 45870 | BM1: 45901 | BN1: 45931 | BO1: 45962 | BP1: 45992 | BQ1: TOTAL-25 | BR1: 46023 | BS1: 46054 | BT1: 46082
C2: G&A | E2: =+SUM(E3:E9) -> 529639.39 | F2: =+SUM(F3:F9) -> 521129.65 | G2: =+SUM(G3:G9) -> 449844.95 | H2: =+SUM(H3:H9) -> 539516.64 | I2: =+SUM(I3:I9) -> 595047.29 | J2: =+SUM(J3:J9) -> 573272.36 | K2: =+SUM(K3:K9) -> 626045.3 | L2: =+SUM(L3:L9) -> 580058.94 | ... P2: =+SUM(P3:P9) -> 487331.92 | Q2: =+SUM(E2:P2) -> 6643793.3 | R2: =+SUM(R3:R9) -> 496330.21 | S2: =+SUM(S3:S9) -> 470237.24 | T2: =+SUM(T3:T9) -> 520189.49 | U2: =+SUM(U3:U9) -> 499512.69 | V2: =+SUM(V3:V9) -> 508752.85 | W2: =+SUM(W3:W9) -> 485176.37 | X2: =+SUM(X3:X9) -> 511823.86 | Y2: =+SUM(Y3:Y9) -> 533833.22 | ... AP2: =+SUM(AP3:AP9) -> 565541.41 | AQ2: =+SUM(AE3:AP9) -> 6808766.7 | AR2: =+SUM(AR3:AR9) -> 555890.58 | AS2: =+SUM(AS3:AS9) -> 559280.72 | AT2: =+SUM(AT3:AT9) -> 606064.3 | AU2: =+SUM(AU3:AU9) -> 559669.09 | AV2: =+SUM(AV3:AV9) -> 526112.61 | AW2: =+SUM(AW3:AW9) -> 469005.45 | AX2: =+SUM(AX3:AX9) -> 495606.34 | AY2: =+SUM(AY3:AY9) -> 513369.51 | ... BC2: =+SUM(BC3:BC9) -> 558203.29 | BD2: =+SUM(AR3:BC9) -> 6405879.9 | BE2: =+SUM(BE3:BE9) -> 556900.79 | BF2: =+SUM(BF3:BF9) -> 518655.69 | BG2: =+SUM(BG3:BG9) -> 584143.67 | BH2: =+SUM(BH3:BH9) -> 528453.87 | BI2: =+SUM(BI3:BI9) -> 511915.84 | BJ2: =+SUM(BJ3:BJ9) -> 492264.29 | BK2: =+SUM(BK3:BK9) -> 513867.29 | BL2: =+SUM(BL3:BL9) -> 523272.85 | ... BP2: =+SUM(BP3:BP9) -> 558082.42 | BQ2: =+SUM(BE3:BP9) -> 6396204.5 | BR2: =+SUM(BR3:BR9) -> 571371.43 | BS2: =+SUM(BS3:BS9) -> 535508.74 | BT2: =+SUM(BT3:BT9) -> 588516.85
A3: 3110200 | B3: CECOS SSGG | C3: G&A | D3: CAMPAMENTO | E3: 296078.94 | F3: 291321.82 | G3: 244148.25 | H3: 200134.36 | I3: 220733.52 | J3: 212656.08 | K3: 232232.27 | L3: 215173.57 | M3: 250198.89 | N3: 220115 | O3: 280563.34 | P3: 209079.54 | Q3: =+SUM(E3:P3) -> 2872435.6 | R3: 199067.13 | S3: 192830.31 | T3: 218852.06 | U3: 205626.53 | V3: 208152.26 | W3: 201717.29 | X3: 213372.09 | Y3: 229073.3 | Z3: 226129.15 | AA3: 235227.31 | AB3: 232155.28 | AC3: 232851.7 | AD3: =+SUM(R3:AC3) -> 2595054.4 | AE3: 231372.38 | AF3: 222326.54 | AG3: 256746.7 | AH3: 237155.18 | AI3: 232691.32 | AJ3: 219251.97 | AK3: 225408.36 | AL3: 234654.75 | AM3: 227590.16 | AN3: 240026.79 | AO3: 230900.65 | AP3: 252282.07 | AQ3: =+SUM(AE3:AP3) -> 2810406.9 | AR3: 259952.87 | AS3: 253727.35 | AT3: 268428.51 | AU3: 240511.98 | AV3: 227879.37 | AW3: 215466.36 | AX3: 225171.75 | AY3: 224274.14 | AZ3: 220081.47 | BA3: 242222.55 | BB3: 231827 | BC3: 247344.72 | BD3: =+SUM(AR3:BC3) -> 2856888.1 | BE3: 249405.86 | BF3: 236255.53 | BG3: 266023.88 | BH3: 242043.73 | BI3: 241503.48 | BJ3: 229532.05 | BK3: 237406.72 | BL3: 242958.31 | BM3: 241651.88 | BN3: 253949.14 | BO3: 246161.81 | BP3: 256373.07 | BQ3: =+SUM(BE3:BP3) -> 2943265.5 | BR3: 256426.38 | BS3: 247221.19 | BT3: 269763.7
A4: 3110200 | B4: CECOS SSGG | C4: G&A | D4: PIONERO CORE SHAKE | E4: 19154.899 | F4: 18847.136 | G4: 10303.644 | H4: 23329.722 | I4: 25730.972 | J4: 24789.383 | K4: 27071.385 | L4: 25082.847 | M4: 29165.759 | N4: 27766.931 | O4: 32579.632 | P4: 28232.264 | Q4: =+SUM(E4:P4) -> 292054.57 | R4: 27932.413 | S4: 25882.913 | T4: 28334.765 | U4: 27646.324 | V4: 28666.28 | W4: 27454.299 | X4: 28516.746 | Y4: 28457.139 | Z4: 27611.179 | AA4: 28511.153 | AB4: 27374.551 | AC4: 27314 | AD4: =+SUM(R4:AC4) -> 333701.76 | AE4: 28349.339 | AF4: 25737.532 | AG4: 28265.55 | AH4: 149463.01 | AI4: 28689.814 | AJ4: 27537.283 | AK4: 28596.53 | AL4: 28369.184 | AM4: 27686.76 | AN4: 28641.84 | AO4: 27806.54 | AP4: 28597.66 | AQ4: =+SUM(AE4:AP4) -> 457741.04 | AR4: 28619.81 | AS4: 26797.665 | AT4: 28541.16 | AU4: 27665.725 | AV4: 28485.43 | AW4: 27576.05 | AX4: 4775.8258 | AY4: 4758.9589 | AZ4: 4599.0374 | BA4: 4749.0988 | BB4: 4579.4958 | BC4: 4755.4646 | BD4: =+SUM(AR4:BC4) -> 195903.72 | BE4: 4768.0865 | BF4: 4277.5996 | BG4: 4739.5282 | BH4: 4599.4706 | BI4: 4772.9154 | BJ4: 4614.9392 | BK4: 4748.939 | BL4: 4763.2957 | BM4: 4592.8228 | BN4: 4789.6747 | BO4: 4599 | BP4: 4771.87 | BQ4: =+SUM(BE4:BP4) -> 56038.142 | BR4: 4766.4638 | BS4: 4300.103 | BT4: 4744.4458
A5: 3110200 | B5: CECOS SSGG | C5: G&A | D5: VILLA COLABORADORES | E5: 31924.92 | F5: 31411.98 | G5: 17172.788 | H5: 0 | I5: 0 | J5: 0 | K5: 0 | L5: 0 | M5: 0 | N5: 0 | O5: 0 | P5: 0 | Q5: =+SUM(E5:P5) -> 80509.688 | R5: 0 | S5: 0 | T5: 0 | U5: 0 | V5: 0 | W5: 0 | X5: 0 | Y5: 0 | AD5: =+SUM(R5:AC5) -> 0 | AE5: 0 | AF5: 0 | AM5: 0 | AN5: 0 | AO5: 0 | AP5: 0 | AQ5: =+SUM(AE5:AP5) -> 0 | AX5: 370.27764 | AY5: 368.96991 | AZ5: 356.57094 | BA5: 368.20544 | BB5: 355.05584 | BC5: 368.699 | BD5: =+SUM(AR5:BC5) -> 2187.7788 | BE5: 369.6776 | BF5: 331.64934 | BG5: 367.46342 | BH5: 356.60452 | BI5: 370.05198 | BJ5: 357.80383 | BK5: 368.19306 | BL5: 369.30616 | BM5: 356.08911 | BN5: 371.35136 | BO5: 356.57 | BP5: 369.97 | BQ5: =+SUM(BE5:BP5) -> 4344.7304 | BR5: 369.55178 | BS5: 333.39406 | BT5: 367.84469
A6: 3110200 | B6: CECOS SSGG | C6: G&A | D6: GARITA | E6: 33192.529 | F6: 32659.223 | G6: 36679.265 | H6: 32454.22 | I6: 35794.625 | J6: 34484.77 | K6: 37659.287 | L6: 34893.012 | M6: 40572.794 | N6: 33863.846 | O6: 32705.352 | P6: 33904.79 | Q6: =+SUM(E6:P6) -> 418863.71 | R6: 32281.156 | S6: 31269.78 | T6: 35489.523 | U6: 33344.843 | V6: 33754.421 | W6: 32710.912 | X6: 34600.88 | Y6: 37147.022 | Z6: 36669.591 | AA6: 38144.969 | AB6: 37646.801 | AC6: 37759.73 | AD6: =+SUM(R6:AC6) -> 420819.63 | AE6: 37519.845 | AF6: 36052.953 | AG6: 41634.601 | AH6: 38457.596 | AI6: 37733.728 | AJ6: 35554.373 | AK6: 36552.707 | AL6: 38052.122 | AM6: 36906.512 | AN6: 38923.264 | AO6: 37443.348 | AP6: 40910.606 | AQ6: =+SUM(AE6:AP6) -> 455741.66 | AR6: 42154.519 | AS6: 41144.976 | AT6: 43528.948 | AU6: 39001.942 | AV6: 36953.412 | AW6: 34940.491 | AX6: 36514.337 | AY6: 36368.78 | AZ6: 35688.887 | BA6: 39279.333 | BB6: 37593.567 | BC6: 40109.954 | BD6: =+SUM(AR6:BC6) -> 463279.15 | BE6: 40444.193 | BF6: 38311.707 | BG6: 43139.008 | BH6: 39250.334 | BI6: 39162.727 | BJ6: 37221.414 | BK6: 38498.387 | BL6: 39398.645 | BM6: 39186.792 | BN6: 41180.941 | BO6: 39918.13 | BP6: 41574.01 | BQ6: =+SUM(BE6:BP6) -> 477286.29 | BR6: 41582.657 | BS6: 40089.923 | BT6: 43745.466
A7: 3110200 | B7: CECOS TI | C7: G&A | D7: ANTENA | E7: 29873.276 | F7: 29393.301 | G7: 33011.338 | H7: 37863.257 | I7: 41760.396 | J7: 40232.232 | K7: 43935.835 | L7: 40708.514 | M7: 47334.926 | N7: 28219.871 | O7: 45446.134 | P7: 39555.589 | Q7: =+SUM(E7:P7) -> 457334.67 | R7: 37661.349 | S7: 36481.41 | T7: 41404.443 | U7: 38902.316 | V7: 39380.158 | W7: 38162.731 | X7: 40367.693 | Y7: 43338.192 | Z7: 42781.19 | AA7: 44502.464 | AB7: 43921.268 | AC7: 44053.02 | AD7: =+SUM(R7:AC7) -> 490956.23 | AE7: 43773.152 | AF7: 42061.778 | AG7: 48573.701 | AH7: 44867.195 | AI7: 44022.683 | AJ7: 41480.102 | AK7: 42644.825 | AL7: 44394.143 | AM7: 43057.598 | AN7: 45410.474 | AO7: 43683.906 | AP7: 47729.041 | AQ7: =+SUM(AE7:AP7) -> 531698.6 | AR7: 49180.272 | AS7: 48002.472 | AT7: 50783.76 | AU7: 45502.266 | AV7: 43112.314 | AW7: 40763.906 | AX7: 42600.06 | AY7: 42430.244 | AZ7: 41637.034 | BA7: 45825.888 | BB7: 43859.161 | BC7: 46794.946 | BD7: =+SUM(AR7:BC7) -> 540492.32 | BE7: 47184.892 | BF7: 44696.992 | BG7: 50328.843 | BH7: 45792.056 | BI7: 45689.848 | BJ7: 43424.983 | BK7: 44914.785 | BL7: 45965.086 | BM7: 45717.924 | BN7: 48044.432 | BO7: 46571.15 | BP7: 48503.01 | BQ7: =+SUM(BE7:BP7) -> 556834 | BR7: 48513.1 | BS7: 46771.577 | BT7: 51036.377
A8: 3110200 | B8: CECOS SSGG | C8: G&A | D8: MAIN OFFICIE | E8: 45494.527 | F8: 44763.564 | G8: 24472.039 | H8: 55410.09 | I8: 61113.265 | J8: 58876.91 | K8: 64296.86 | L8: 59573.913 | M8: 69271.18 | N8: 30095.843 | O8: 56471.515 | P8: 32363.579 | Q8: =+SUM(E8:P8) -> 602203.29 | R8: 32269.565 | S8: 30354.446 | T8: 35593.611 | U8: 33400.767 | V8: 31920.785 | W8: 30119.755 | X8: 31434.422 | Y8: 31549.555 | Z8: 32033.117 | AA8: 34538.246 | AB8: 35724.927 | AC8: 37590.59 | AD8: =+SUM(R8:AC8) -> 396529.79 | AE8: 40744.15 | AF8: 39677.324 | AG8: 44880.197 | AH8: 234391.03 | AI8: 38413.3 | AJ8: 37849.76 | AK8: 39959.65 | AL8: 41163.77 | AM8: 39859.39 | AN8: 44166.99 | AO8: 42219.2 | AP8: 44160.48 | AQ8: =+SUM(AE8:AP8) -> 687485.25 | AR8: 46852.29 | AS8: 46294.409 | AT8: 49409.51 | AU8: 43874.231 | AV8: 42116.85 | AW8: 40408.88 | AX8: 42126.281 | AY8: 42487.071 | AZ8: 42209.277 | BA8: 46025.894 | BB8: 45880.358 | BC8: 48864.631 | BD8: =+SUM(AR8:BC8) -> 536549.68 | BE8: 51088.233 | BF8: 47209.134 | BG8: 51665.259 | BH8: 47534.151 | BI8: 46122.616 | BJ8: 42693.837 | BK8: 44236.8 | BL8: 44956.285 | BM8: 45635.536 | BN8: 48495.98 | BO8: 47453.96 | BP8: 50596.89 | BQ8: =+SUM(BE8:BP8) -> 567688.68 | BR8: 53325.771 | BS8: 48052.733 | BT8: 52639.928
A9: 3110151 | B9: CECOS LOGIST | C9: G&A | D9: GRIFO PRIMAX | E9: 73920.302 | F9: 72732.62 | G9: 84057.629 | H9: 190325 | I9: 209914.52 | J9: 202232.99 | K9: 220849.67 | L9: 204627.08 | M9: 237935.68 | N9: 59651.807 | O9: 219948.37 | P9: 144196.16 | Q9: =+SUM(E9:P9) -> 1920391.8 | R9: 167118.6 | S9: 153418.39 | T9: 160515.09 | U9: 160591.91 | V9: 166878.94 | W9: 155011.38 | X9: 163532.02 | Y9: 164268.01 | Z9: 161239.59 | AA9: 167792.28 | AB9: 159155.44 | AC9: 164551.55 | AD9: =+SUM(R9:AC9) -> 1944073.2 | AE9: 161587.25 | AF9: 151234.82 | AG9: 168001.19 | AH9: 130473.4 | AI9: 167975.89 | AJ9: 146353.28 | AK9: 162333.23 | AL9: 169861.75 | AM9: 155388 | AN9: 152430.65 | AO9: 148192.26 | AP9: 151861.55 | AQ9: =+SUM(AE9:AP9) -> 1865693.3 | AR9: 129130.82 | AS9: 143313.84 | AT9: 165372.41 | AU9: 163112.95 | AV9: 147565.23 | AW9: 109849.76 | AX9: 144047.81 | AY9: 162681.35 | AZ9: 156862.41 | BA9: 160850.99 | BB9: 157826.77 | BC9: 169964.88 | BD9: =+SUM(AR9:BC9) -> 1810579.2 | BE9: 163639.85 | BF9: 147573.08 | BG9: 167879.68 | BH9: 148877.53 | BI9: 134294.2 | BJ9: 134419.26 | BK9: 143693.47 | BL9: 144861.93 | BM9: 140369.21 | BN9: 158825.91 | BO9: 150419.51 | BP9: 155893.6 | BQ9: =+SUM(BE9:BP9) -> 1790747.2 | BR9: 166387.51 | BS9: 148739.82 | BT9: 166219.09
C10: MANTENIMIENTO | E10: =+SUM(E11:E12) -> 195384.46 | F10: =+SUM(F11:F12) -> 258852.17 | G10: =+SUM(G11:G12) -> 128346.75 | H10: =+SUM(H11:H12) -> 240696.64 | I10: =+SUM(I11:I12) -> 265470.75 | J10: =+SUM(J11:J12) -> 255756.21 | K10: =+SUM(K11:K12) -> 279300.01 | L10: =+SUM(L11:L12) -> 258783.94 | ... P10: =+SUM(P11:P12) -> 71978.579 | Q10: =+SUM(E10:P10) -> 2659139.8 | R10: =+SUM(R11:R12) -> 73833.943 | S10: =+SUM(S11:S12) -> 66023.882 | T10: =+SUM(T11:T12) -> 72545.389 | U10: =+SUM(U11:U12) -> 76041.738 | V10: =+SUM(V11:V12) -> 76728.68 | W10: =+SUM(W11:W12) -> 73401.198 | X10: =+SUM(X11:X12) -> 75380.345 | Y10: =+SUM(Y11:Y12) -> 74869.14 | ... AP10: =+SUM(AP11:AP12) -> 79596.68 | AQ10: =+SUM(AE10:AP10) -> 952202.99 | AR10: =+SUM(AR11:AR12) -> 83666.1 | AS10: =+SUM(AS11:AS12) -> 82156.461 | AT10: =+SUM(AT11:AT12) -> 87343.82 | AU10: =+SUM(AU11:AU12) -> 82834.544 | AV10: =+SUM(AV11:AV12) -> 82031.96 | AW10: =+SUM(AW11:AW12) -> 80496.449 | AX10: =+SUM(AX11:AX12) -> 81844.979 | AY10: =+SUM(AY11:AY12) -> 88141.096 | ... BC10: =+SUM(BC11:BC12) -> 75666.224 | BD10: =+SUM(AR10:BC10) -> 983040.22 | BE10: =+SUM(BE11:BE12) -> 91053.947 | BF10: =+SUM(BF11:BF12) -> 79453.54 | BG10: =+SUM(BG11:BG12) -> 90844.701 | BH10: =+SUM(BH11:BH12) -> 88476.467 | BI10: =+SUM(BI11:BI12) -> 83516.951 | BJ10: =+SUM(BJ11:BJ12) -> 90660.86 | BK10: =+SUM(BK11:BK12) -> 83600.636 | BL10: =+SUM(BL11:BL12) -> 82755.69 | ... BP10: =+SUM(BP11:BP12) -> 83210.45 | BQ10: =+SUM(BE10:BP10) -> 1008814.4 | BR10: =+SUM(BR11:BR12) -> 90072.764 | BS10: =+SUM(BS11:BS12) -> 83353.768 | BT10: =+SUM(BT11:BT12) -> 89590.074
A11: 1290900 | B11: CECOS MTTO | C11: MANTENIMIENTO | D11: TRUCK SHOP | E11: 164097.18 | F11: 160346.92 | G11: 88269.792 | H11: 199862.26 | I11: 220433.42 | J11: 212366.97 | K11: 231916.54 | L11: 214881.03 | M11: 249858.73 | N11: 137345.77 | O11: 187808.17 | P11: 43661.91 | Q11: =+SUM(E11:P11) -> 2110848.7 | R11: 42635.156 | S11: 40296.26 | T11: 43883.356 | U11: 47688.688 | V11: 48136.346 | W11: 45445.939 | X11: 47223.454 | Y11: 47125.153 | Z11: 47633.179 | AA11: 50499.108 | AB11: 48100.199 | AC11: 47363.23 | AD11: =+SUM(R11:AC11) -> 556030.07 | AE11: 50059.026 | AF11: 46812.253 | AG11: 57312.647 | AH11: 44903.936 | AI11: 56756.914 | AJ11: 50301.339 | AK11: 55674.773 | AL11: 52509.791 | AM11: 49680.12 | AN11: 51205.22 | AO11: 50761.4 | AP11: 50520.21 | AQ11: =+SUM(AE11:AP11) -> 616497.63 | AR11: 53998.71 | AS11: 53877.938 | AT11: 56919.38 | AU11: 55422.982 | AV11: 54613.37 | AW11: 54494.41 | AX11: 55907.089 | AY11: 61099.808 | AZ11: 58179.899 | BA11: 49965.569 | BB11: 52068.132 | BC11: 48822.021 | BD11: =+SUM(AR11:BC11) -> 655369.31 | BE11: 62887.978 | BF11: 51453.746 | BG11: 59562.784 | BH11: 63418.016 | BI11: 56780.68 | BJ11: 63506.332 | BK11: 55462.988 | BL11: 56736.495 | BM11: 51173.693 | BN11: 52380.92 | BO11: 50247.16 | BP11: 51917.06 | BQ11: =+SUM(BE11:BP11) -> 675527.85 | BR11: 57146.406 | BS11: 54644.687 | BT11: 58743.693
A12: 1290900 | B12: CECOS MTTO | C12: MANTENIMIENTO | D12: SS.AA S.E MINA JUSTA | E12: 31287.287 | F12: 98505.249 | G12: 40076.959 | H12: 40834.381 | I12: 45037.328 | J12: 43389.249 | K12: 47383.473 | L12: 43902.904 | M12: 51049.29 | N12: 35572.402 | O12: 42935.888 | P12: 28316.669 | Q12: =+SUM(E12:P12) -> 548291.08 | R12: 31198.786 | S12: 25727.622 | T12: 28662.033 | U12: 28353.05 | V12: 28592.334 | W12: 27955.258 | X12: 28156.891 | Y12: 27743.988 | Z12: 27002.255 | AA12: 27832.066 | AB12: 26906.154 | AC12: 27504.16 | AD12: =+SUM(R12:AC12) -> 335634.6 | AE12: 27741.332 | AF12: 25144.98 | AG12: 28126.378 | AH12: 27736.782 | AI12: 28134.219 | AJ12: 27702.545 | AK12: 27866.392 | AL12: 29080.924 | AM12: 28215.22 | AN12: 28763.61 | AO12: 28116.51 | AP12: 29076.47 | AQ12: =+SUM(AE12:AP12) -> 335705.36 | AR12: 29667.39 | AS12: 28278.523 | AT12: 30424.44 | AU12: 27411.562 | AV12: 27418.59 | AW12: 26002.039 | AX12: 25937.889 | AY12: 27041.288 | AZ12: 25884.762 | BA12: 26646.231 | BB12: 26113.991 | BC12: 26844.203 | BD12: =+SUM(AR12:BC12) -> 327670.91 | BE12: 28165.969 | BF12: 27999.794 | BG12: 31281.917 | BH12: 25058.451 | BI12: 26736.271 | BJ12: 27154.528 | BK12: 28137.648 | BL12: 26019.194 | BM12: 25409.092 | BN12: 27751.157 | BO12: 28279.12 | BP12: 31293.39 | BQ12: =+SUM(BE12:BP12) -> 333286.53 | BR12: 32926.357 | BS12: 28709.081 | BT12: 30846.382
C13: MINA | E13: =+SUM(E14:E17) -> 1290708.4 | F13: =+SUM(F14:F17) -> 1258822.6 | G13: =+SUM(G14:G17) -> 2858940.6 | H13: =+SUM(H14:H17) -> 2955521.2 | I13: =+SUM(I14:I17) -> 3259723.1 | J13: =+SUM(J14:J17) -> 3140438.1 | K13: =+SUM(K14:K17) -> 3429533 | L13: =+SUM(L14:L17) -> 3177615.5 | ... P13: =+SUM(P14:P17) -> 2736447.9 | Q13: =+SUM(E13:P13) -> 34611127 | R13: =+SUM(R14:R17) -> 2565721.4 | S13: =+SUM(S14:S17) -> 2556635.5 | T13: =+SUM(T14:T17) -> 3123647 | U13: =+SUM(U14:U17) -> 3175170.5 | V13: =+SUM(V14:V17) -> 3216182.8 | W13: =+SUM(W14:W17) -> 2794760.7 | X13: =+SUM(X14:X17) -> 3073085.5 | Y13: =+SUM(Y14:Y17) -> 3005132.6 | ... AP13: =+SUM(AP14:AP17) -> 3378491.8 | AQ13: =+SUM(AE13:AP13) -> 38293834 | AR13: =+SUM(AR14:AR17) -> 3307838.1 | AS13: =+SUM(AS14:AS17) -> 3255397.6 | AT13: =+SUM(AT14:AT17) -> 3425270.3 | AU13: =+SUM(AU14:AU17) -> 3051020.4 | AV13: =+SUM(AV14:AV17) -> 3161604.5 | AW13: =+SUM(AW14:AW17) -> 3275010.3 | AX13: =+SUM(AX14:AX17) -> 3101494.6 | AY13: =+SUM(AY14:AY17) -> 3337585.1 | ... BC13: =+SUM(BC14:BC17) -> 3005658.2 | BD13: =+SUM(AR13:BC13) -> 38178310 | BE13: =+SUM(BE14:BE17) -> 3108418.4 | BF13: =+SUM(BF14:BF17) -> 2923446.8 | BG13: =+SUM(BG14:BG17) -> 3364575.7 | BH13: =+SUM(BH14:BH17) -> 3387846.8 | BI13: =+SUM(BI14:BI17) -> 3733088.7 | BJ13: =+SUM(BJ14:BJ17) -> 3294299.4 | BK13: =+SUM(BK14:BK17) -> 3186147.9 | BL13: =+SUM(BL14:BL17) -> 3475384.9 | ... BP13: =+SUM(BP14:BP17) -> 2793216.4 | BQ13: =+SUM(BE13:BP13) -> 38942144 | BR13: =+SUM(BR14:BR17) -> 3279420.1 | BS13: =+SUM(BS14:BS17) -> 2878742.2 | BT13: =+SUM(BT14:BT17) -> 3008962.8
A14: 1112120 | B14: CECOS MINA | C14: MINA | D14: PALAS ELECTRICAS | E14: 924181.48 | F14: 901350.37 | G14: 2221771.9 | H14: 2216380.8 | I14: 2444505.5 | J14: 2355052.2 | K14: 2571848 | L14: 2382932.1 | M14: 2770818.8 | N14: 2748485.7 | O14: 2466422.9 | P14: 2069899.4 | Q14: =+SUM(E14:P14) -> 26073649 | R14: 1918075.9 | S14: 1922551.5 | T14: 2369634.4 | U14: 2410953.4 | V14: 2437672.6 | W14: 2110391.1 | X14: 2327431.5 | Y14: 2272664.5 | Z14: 2124711.2 | AA14: 2458020.4 | AB14: 2107986.9 | AC14: 2143675 | AD14: =+SUM(R14:AC14) -> 26603768 | AE14: 1900035.6 | AF14: 2044662.6 | AG14: 2368873.2 | AH14: 2045384.3 | AI14: 2585331.6 | AJ14: 2464798.2 | AK14: 2632718 | AL14: 2617484.2 | AM14: 2589437.1 | AN14: 2634896.6 | AO14: 2662629 | AP14: 2579159 | AQ14: =+SUM(AE14:AP14) -> 29125409 | AR14: 2541582.3 | AS14: 2490494.5 | AT14: 2607093.2 | AU14: 2309969.7 | AV14: 2407651.3 | AW14: 2523458.9 | AX14: 2472188.6 | AY14: 2660170.7 | AZ14: 2551443.6 | BA14: 2544286.8 | BB14: 2281275.7 | BC14: 2394279.8 | BD14: =+SUM(AR14:BC14) -> 29783895 | BE14: 2476787.1 | BF14: 2329796.2 | BG14: 2681521 | BH14: 2701114 | BI14: 2977934.9 | BJ14: 2626965.9 | BK14: 2504054.2 | BL14: 2771267 | BM14: 2686641.9 | BN14: 2780572.3 | BO14: 2244980.7 | BP14: 2224997.1 | BQ14: =+SUM(BE14:BP14) -> 31006632 | BR14: 2613456.9 | BS14: 2293966.6 | BT14: 2397108.7
A15: 1110101 | B15: CECOS MINA | C15: MINA | D15: PERFORADORAS ELECTRICAS | E15: 231045.37 | F15: 225337.59 | G15: 555442.97 | H15: 554095.21 | I15: 611126.38 | J15: 588763.06 | K15: 642962 | L15: 595733.02 | M15: 692704.69 | N15: 687121.43 | O15: 616605.73 | P15: 517474.86 | Q15: =+SUM(E15:P15) -> 6518412.3 | R15: 479518.99 | S15: 480637.88 | T15: 592408.59 | U15: 602738.35 | V15: 609418.15 | W15: 527597.77 | X15: 581857.88 | Y15: 568166.12 | Z15: 531177.79 | AA15: 614505.11 | AB15: 526996.73 | AC15: 535918.75 | AD15: =+SUM(R15:AC15) -> 6650942.1 | AE15: 475008.91 | AF15: 511165.64 | AG15: 592218.29 | AH15: 511346.07 | AI15: 646332.9 | AJ15: 616199.55 | AK15: 658179.49 | AL15: 654371.04 | AM15: 647359.27 | AN15: 658724.16 | AO15: 665657.25 | AP15: 644789.75 | AQ15: =+SUM(AE15:AP15) -> 7281352.3 | AR15: 635395.57 | AS15: 622623.62 | AT15: 651773.28 | AU15: 577492.42 | AV15: 601912.82 | AW15: 630864.73 | AX15: 618047.16 | AY15: 665042.67 | AZ15: 637860.9 | BA15: 636071.71 | BB15: 570318.91 | BC15: 598569.94 | BD15: =+SUM(AR15:BC15) -> 7445973.7 | BE15: 619196.78 | BF15: 582449.04 | BG15: 670380.26 | BH15: 675278.5 | BI15: 744483.74 | BJ15: 656741.48 | BK15: 670870.7 | BL15: 692816.75 | BM15: 702255.82 | BN15: 665381.59 | BO15: 561245.17 | BP15: 556249.28 | BQ15: =+SUM(BE15:BP15) -> 7797349.1 | BR15: 653364.21 | BS15: 573491.66 | BT15: 599277.18
A16: 3110151 | B16: CECOS MINA | C16: MINA | D16: CANCHA NITRATOS | E16: 35915.435 | F16: 35028.175 | G16: 19319.333 | H16: 43743.228 | I16: 48245.572 | J16: 46480.093 | K16: 50758.846 | L16: 47030.338 | M16: 54685.799 | N16: 32799.007 | O16: 60191.047 | P16: 33295.698 | Q16: =+SUM(E16:P16) -> 507492.57 | R16: 33943.901 | S16: 30263.629 | T16: 32723.513 | U16: 32536.522 | V16: 34880.438 | W16: 32310.349 | X16: 32493.205 | Y16: 32408.266 | Z16: 32494.484 | AA16: 34681.794 | AB16: 32184.34 | AC16: 32111.4 | AD16: =+SUM(R16:AC16) -> 393031.84 | AE16: 33333.762 | AF16: 30255.645 | AG16: 33230.275 | AH16: 27308.809 | AI16: 33734.099 | AJ16: 32374.083 | AK16: 33688.508 | AL16: 33420.679 | AM16: 32616.76 | AN16: 33741.87 | AO16: 32757.85 | AP16: 32610.63 | AQ16: =+SUM(AE16:AP16) -> 389072.97 | AR16: 27178.74 | AS16: 27210.217 | AT16: 33623.34 | AU16: 32591.96 | AV16: 33557.6 | AW16: 32486.28 | AX16: 2584.3868 | AY16: 2575.2594 | AZ16: 2488.7196 | BA16: 2569.9237 | BB16: 2478.1449 | BC16: 2573.3685 | BD16: =+SUM(AR16:BC16) -> 201917.94 | BE16: 2580.1987 | BF16: 2314.777 | BG16: 2564.7447 | BH16: 2488.954 | BI16: 2582.8118 | BJ16: 2497.3247 | BK16: 2569.8372 | BL16: 2577.6062 | BM16: 2485.3567 | BN16: 2591.8809 | BO16: 2488.7 | BP16: 2582.25 | BQ16: =+SUM(BE16:BP16) -> 30324.442 | BR16: 2579.3206 | BS16: 2326.9545 | BT16: 2567.4058
A17: 1190900 | B17: CECOS MINA | C17: MINA | D17: CAMBIO DE GUARDIA | E17: 99566.121 | F17: 97106.425 | G17: 62406.422 | H17: 141301.89 | I17: 155845.63 | J17: 150142.67 | K17: 163964.15 | L17: 151920.11 | M17: 176649.22 | N17: 71582.321 | O17: 125310.34 | P17: 115777.94 | Q17: =+SUM(E17:P17) -> 1511573.2 | R17: 134182.58 | S17: 123182.42 | T17: 128880.5 | U17: 128942.18 | V17: 134211.57 | W17: 124461.47 | X17: 131302.84 | Y17: 131893.78 | Z17: 129462.21 | AA17: 134723.48 | AB17: 127788.8 | AC17: 132121.45 | AD17: =+SUM(R17:AC17) -> 1561153.3 | AE17: 129741.35 | AF17: 121429.19 | AG17: 134891.22 | AH17: 104759.47 | AI17: 134870.91 | AJ17: 117509.72 | AK17: 130340.31 | AL17: 136385.1 | AM17: 124763.85 | AN17: 122389.35 | AO17: 118986.27 | AP17: 121932.36 | AQ17: =+SUM(AE17:AP17) -> 1497999.1 | AR17: 103681.52 | AS17: 115069.3 | AT17: 132780.52 | AU17: 130966.36 | AV17: 118482.83 | AW17: 88200.37 | AX17: 8674.4118 | AY17: 9796.5044 | AZ17: 9446.0941 | BA17: 9686.2821 | BB17: 9504.1667 | BC17: 10235.116 | BD17: =+SUM(AR17:BC17) -> 746523.48 | BE17: 9854.3176 | BF17: 8886.8258 | BG17: 10109.686 | BH17: 8965.3112 | BI17: 8087.1733 | BJ17: 8094.6731 | BK17: 8653.1968 | BL17: 8723.5597 | BM17: 8453.01 | BN17: 9564.3341 | BO17: 9058.11 | BP17: 9387.75 | BQ17: =+SUM(BE17:BP17) -> 107837.95 | BR17: 10019.686 | BS17: 8956.9598 | BT17: 10009.544
C18: PLANTA | Q18: =+SUM(F18:P18) -> 0
C19: SULFUROS | E19: =+SUM(E20:E27) -> 393779.22 | F19: =+SUM(F20:F27) -> 1559477.8 | G19: =+SUM(G20:G27) -> 6277467.4 | H19: =+SUM(H20:H27) -> 10078160 | I19: =+SUM(I20:I27) -> 11115472 | J19: =+SUM(J20:J27) -> 10708716 | K19: =+SUM(K20:K27) -> 11694514 | L19: =+SUM(L20:L27) -> 10835490 | ... P19: =+SUM(P20:P27) -> 10362455 | Q19: =+SUM(E19:P19) -> 1.1290371e+08 | R19: =+SUM(R20:R27) -> 13564449 | S19: =+SUM(S20:S27) -> 11196817 | T19: =+SUM(T20:T27) -> 12536847 | U19: =+SUM(U20:U27) -> 13503842 | V19: =+SUM(V20:V27) -> 12531317 | W19: =+SUM(W20:W27) -> 13648845 | X19: =+SUM(X20:X27) -> 11893972 | Y19: =+SUM(Y20:Y27) -> 13633960 | ... AP19: =+SUM(AP20:AP27) -> 12315444 | AQ19: =+SUM(AE19:AP19) -> 1.3966203e+08 | AR19: =+SUM(AR20:AR27) -> 11393503 | AS19: =+SUM(AS20:AS27) -> 12057790 | AT19: =+SUM(AT20:AT27) -> 13132659 | AU19: =+SUM(AU20:AU27) -> 6531960 | AV19: =+SUM(AV20:AV27) -> 13320568 | AW19: =+SUM(AW20:AW27) -> 12333057 | AX19: =+SUM(AX20:AX27) -> 10683132 | AY19: =+SUM(AY20:AY27) -> 13424471 | ... BC19: =+SUM(BC20:BC27) -> 13548032 | BD19: =+SUM(AR19:BC19) -> 1.4580403e+08 | BE19: =+SUM(BE20:BE27) -> 11517385 | BF19: =+SUM(BF20:BF27) -> 12591986 | BG19: =+SUM(BG20:BG27) -> 13268736 | BH19: =+SUM(BH20:BH27) -> 11367091 | BI19: =+SUM(BI20:BI27) -> 13911015 | BJ19: =+SUM(BJ20:BJ27) -> 13571888 | BK19: =+SUM(BK20:BK27) -> 14121232 | BL19: =+SUM(BL20:BL27) -> 12879591 | ... BP19: =+SUM(BP20:BP27) -> 13451455 | BQ19: =+SUM(BE19:BP19) -> 1.5713161e+08 | BR19: =+SUM(BR20:BR27) -> 12396474 | BS19: =+SUM(BS20:BS27) -> 12676406 | BT19: =+SUM(BT20:BT27) -> 14221437
A20: 2110101 | B20: CECOS PLANTA | C20: SULFUROS | D20: CHANCADO PRIMARIO | E20: 51534.99 | F20: 54473.825 | G20: 162766.21 | H20: 122320.59 | I20: 134910.64 | J20: 129973.78 | K20: 141938.59 | L20: 131512.45 | M20: 150075.98 | N20: 149565.81 | O20: 133155.31 | P20: 171330.87 | Q20: =+SUM(E20:P20) -> 1533559 | R20: 209438.2 | S20: 204310.97 | T20: 165994.35 | U20: 201566.85 | V20: 223033.52 | W20: 181065.47 | X20: 237375.72 | Y20: 224783.84 | Z20: 234846.71 | AA20: 234683.61 | AB20: 243364.86 | AC20: 255375.77 | AD20: =+SUM(R20:AC20) -> 2615839.9 | AE20: 247191.44 | AF20: 237572.32 | AG20: 281309.06 | AH20: 405757.65 | AI20: 272462.83 | AJ20: 209432.67 | AK20: 285122.06 | AL20: 282473.6 | AM20: 282114.48 | AN20: 234924.77 | AO20: 250968.87 | AP20: 271543.48 | AQ20: =+SUM(AE20:AP20) -> 3260873.2 | AR20: 263501.72 | AS20: 269436.28 | AT20: 258988.96 | AU20: 272067.83 | AV20: 241781.87 | AW20: 170277 | AX20: 244313.05 | AY20: 270571.22 | AZ20: 274037.13 | BA20: 268174.52 | BB20: 276472.89 | BC20: 304017.12 | BD20: =+SUM(AR20:BC20) -> 3113639.6 | BE20: 281894.11 | BF20: 220753.78 | BG20: 303574.92 | BH20: 263481.25 | BI20: 221887.72 | BJ20: 241934.65 | BK20: 262032.05 | BL20: 254250.24 | BM20: 260150.28 | BN20: 247808.69 | BO20: 273151.16 | BP20: 274729.45 | BQ20: =+SUM(BE20:BP20) -> 3105648.3 | BR20: 298968.63 | BS20: 273491.08 | BT20: 274821.81
A21: 2110102 | B21: CECOS PLANTA | C21: SULFUROS | D21: CIRCUITO DE CHANCADO SECUNDARIO | E21: 269138.05 | F21: 136199.45 | G21: 53510.584 | H21: 252056.19 | I21: 277999.49 | J21: 267826.49 | K21: 292481.42 | L21: 270997.1 | M21: 415493.73 | N21: 781975.73 | O21: 300564.7 | P21: 373979.29 | Q21: =+SUM(E21:P21) -> 3692222.2 | R21: 493271.2 | S21: 391077.51 | T21: 443501.98 | U21: 465718.05 | V21: 430991.02 | W21: 479842.08 | X21: 415370.61 | Y21: 492443.42 | Z21: 447892.27 | AA21: 407317.03 | AB21: 394372.9 | AC21: 517368.62 | AD21: =+SUM(R21:AC21) -> 5379166.7 | AE21: 458456.72 | AF21: 477041.02 | AG21: 543244.7 | AH21: 408334.89 | AI21: 500145.43 | AJ21: 420857.9 | AK21: 408050.94 | AL21: 387771.05 | AM21: 442403.68 | AN21: 445698.02 | AO21: 378688.61 | AP21: 479230.26 | AQ21: =+SUM(AE21:AP21) -> 5349923.2 | AR21: 457458.03 | AS21: 471155.11 | AT21: 500951.44 | AU21: 224684.11 | AV21: 482272.1 | AW21: 428454.84 | AX21: 363686.33 | AY21: 474591.3 | AZ21: 434708.74 | BA21: 485173.01 | BB21: 444798.13 | BC21: 448269.63 | BD21: =+SUM(AR21:BC21) -> 5216202.8 | BE21: 381048.53 | BF21: 419387.12 | BG21: 451642.28 | BH21: 396385.53 | BI21: 479099.29 | BJ21: 458355.6 | BK21: 484981.36 | BL21: 421318.92 | BM21: 467136.88 | BN21: 398234.27 | BO21: 442408.63 | BP21: 441414.68 | BQ21: =+SUM(BE21:BP21) -> 5241413.1 | BR21: 396207.58 | BS21: 440017.55 | BT21: 502785.03
A22: 2110103 | B22: CECOS PLANTA | C22: SULFUROS | D22: CIRCUITO DE CHANCADO TERCIARIO | E22: 45612.413 | F22: 90799.636 | G22: 699754.87 | H22: 1233352 | I22: 1360296.8 | J22: 1310518.6 | K22: 1431159.2 | L22: 1326033 | M22: 1985069.4 | N22: 2345927.2 | O22: 1470712.1 | P22: 1495917.1 | Q22: =+SUM(E22:P22) -> 14795152 | R22: 1973084.8 | S22: 1564310.1 | T22: 1774007.9 | U22: 1862872.2 | V22: 1723964.1 | W22: 1919368.3 | X22: 1661482.5 | Y22: 1969773.7 | Z22: 1791569.1 | AA22: 1629268.1 | AB22: 1577491.6 | AC22: 2069474.5 | AD22: =+SUM(R22:AC22) -> 21516667 | AE22: 1833826.9 | AF22: 1908164.1 | AG22: 2172978.8 | AH22: 1633339.6 | AI22: 2000581.7 | AJ22: 1683431.6 | AK22: 1632203.7 | AL22: 1551084.2 | AM22: 1769614.7 | AN22: 1782792.1 | AO22: 1514754.4 | AP22: 1916921 | AQ22: =+SUM(AE22:AP22) -> 21399693 | AR22: 1829832.1 | AS22: 1884620.4 | AT22: 2003805.7 | AU22: 898736.43 | AV22: 1929088.4 | AW22: 1713819.4 | AX22: 1454745.3 | AY22: 1898365.2 | AZ22: 1738835 | BA22: 1940692 | BB22: 1779192.5 | BC22: 1793078.5 | BD22: =+SUM(AR22:BC22) -> 20864811 | BE22: 1524194.1 | BF22: 1677548.5 | BG22: 1806569.1 | BH22: 1585542.1 | BI22: 1916397.1 | BJ22: 1833422.4 | BK22: 1939925.4 | BL22: 1685275.7 | BM22: 1868547.5 | BN22: 1592937.1 | BO22: 1769634.5 | BP22: 1765658.7 | BQ22: =+SUM(BE22:BP22) -> 20965652 | BR22: 1584830.3 | BS22: 1760070.2 | BT22: 2011140.1
A23: 2110110 | B23: CECOS PLANTA | C23: SULFUROS | D23: MOLIENDA PRIMARIA | E23: 27493.767 | F23: 794496.82 | G23: 4322081.3 | H23: 6364078.8 | I23: 7019112.2 | J23: 6762257.6 | K23: 7384761.3 | L23: 6842311.3 | M23: 8443908 | N23: 8783676.4 | O23: 8553538.6 | P23: 7022579.2 | Q23: =+SUM(E23:P23) -> 72320295 | R23: 9290524.2 | S23: 7550139.4 | T23: 8634183.1 | U23: 9303698.9 | V23: 8570392.5 | W23: 9338722.6 | X23: 8096716.2 | Y23: 9221158.6 | Z23: 9346908.3 | AA23: 9232917 | AB23: 7464338 | AC23: 8860912.8 | AD23: =+SUM(R23:AC23) -> 1.0491061e+08 | AE23: 6913970.6 | AF23: 7223808.8 | AG23: 8243486.9 | AH23: 6478153.6 | AI23: 8081661 | AJ23: 7280831.9 | AK23: 8358222.6 | AL23: 7125005.2 | AM23: 7950199.2 | AN23: 7421490.1 | AO23: 6357495 | AP23: 7854101.3 | AQ23: =+SUM(AE23:AP23) -> 89288426 | AR23: 7157157.9 | AS23: 7684870.1 | AT23: 8479672.4 | AU23: 4106470.8 | AV23: 8845532.5 | AW23: 8311378.8 | AX23: 7049537.3 | AY23: 8970292.1 | AZ23: 8141485.7 | BA23: 9283689.7 | BB23: 9031159.6 | BC23: 9228838 | BD23: =+SUM(AR23:BC23) -> 96290085 | BE23: 7853502.3 | BF23: 8613052.1 | BG23: 8899270.4 | BH23: 7605194.9 | BI23: 9443278.1 | BJ23: 9199384.7 | BK23: 9547910.1 | BL23: 8857104.2 | BM23: 9645723.2 | BN23: 8484013.8 | BO23: 9735580.7 | BP23: 9184886.1 | BQ23: =+SUM(BE23:BP23) -> 1.070689e+08 | BR23: 8458272.4 | BS23: 8559467.5 | BT23: 9584391.2
A24: 2110120 | B24: CECOS PLANTA | C24: SULFUROS | D24: FLOTACIÓN | E24: 0 | F24: 340498.64 | G24: 190373.07 | H24: 931027.58 | I24: 1026855.1 | J24: 989278.81 | K24: 1080347.5 | L24: 1000990.2 | M24: 1244834.7 | N24: 871236.88 | O24: 856952.86 | P24: 649326.42 | Q24: =+SUM(E24:P24) -> 9181721.8 | R24: 796581.27 | S24: 722181 | T24: 738950.74 | U24: 818076.12 | V24: 800518.69 | W24: 844008.38 | X24: 752727.75 | Y24: 844833.75 | Z24: 825429 | AA24: 841169.5 | AB24: 767375 | AC24: 926139 | AD24: =+SUM(R24:AC24) -> 9677990.2 | AE24: 765729.5 | AF24: 785183.5 | AG24: 917413.08 | AH24: 775877.96 | AI24: 906714.31 | AJ24: 791413.38 | AK24: 856579.25 | AL24: 761578 | AM24: 806661.75 | AN24: 769088.47 | AO24: 768870.14 | AP24: 896157 | AQ24: =+SUM(AE24:AP24) -> 9801266.3 | AR24: 808160.5 | AS24: 817710.5 | AT24: 883176.81 | AU24: 489880.16 | AV24: 883921.15 | AW24: 834427.69 | AX24: 779067.75 | AY24: 918973.5 | AZ24: 825179 | BA24: 915794.8 | BB24: 851794.55 | BC24: 856163.13 | BD24: =+SUM(AR24:BC24) -> 9864249.5 | BE24: 751373.5 | BF24: 790745.5 | BG24: 862358 | BH24: 749453.19 | BI24: 901027.09 | BJ24: 875298.62 | BK24: 922373.75 | BL24: 853340.75 | BM24: 919326 | BN24: 825252.88 | BO24: 912365.85 | BP24: 867889.33 | BQ24: =+SUM(BE24:BP24) -> 10230804 | BR24: 810969 | BS24: 833248.2 | BT24: 934396.57
A25: 2110130 | B25: CECOS PLANTA | C25: SULFUROS | D25: REMOLIENDA | E25: 0 | F25: 0 | G25: 88.766047 | H25: 9721.3102 | I25: 10721.892 | J25: 10329.539 | K25: 11280.432 | L25: 10451.824 | M25: 0 | N25: 0 | O25: 0 | P25: 0 | Q25: =+SUM(E25:P25) -> 52593.763 | R25: 0 | S25: 0 | T25: 0 | U25: 0 | V25: 13200 | AD25: =+SUM(R25:AC25) -> 13200 | AE25: 0 | AO25: 0 | AP25: 0 | AQ25: =+SUM(AE25:AP25) -> 0 | AR25: 0 | AS25: 0 | AT25: 0 | AU25: 0 | AV25: 0 | AW25: 0 | AX25: 0 | AY25: 0 | AZ25: 0 | BA25: 0 | BB25: 0 | BC25: 0 | BD25: =+SUM(AR25:BC25) -> 0 | BE25: 0 | BF25: 0 | BG25: 0 | BH25: 0 | BI25: 0 | BJ25: 0 | BK25: 0 | BL25: 0 | BM25: 0 | BN25: 0 | BO25: - | BP25: - | BQ25: =+SUM(BE25:BP25) -> 0 | BR25: 0 | BS25: 0 | BT25: 0
A26: 2110140 | B26: CECOS PLANTA | C26: SULFUROS | D26: ESPESAMIENTO Y CARGA DE CONCENTRADO | E26: 0 | F26: 102149.59 | G26: 509335.6 | H26: 779966.54 | I26: 860245.89 | J26: 828766.39 | K26: 905058.98 | L26: 838577.58 | M26: 884476.52 | N26: 340926.65 | O26: 717910.59 | P26: 313054.76 | Q26: =+SUM(E26:P26) -> 7080469.1 | R26: 388424.47 | S26: 386905.55 | T26: 416588.15 | U26: 424816.57 | V26: 381948.94 | W26: 484039.88 | X26: 353562.82 | Y26: 429313.45 | Z26: 400191.81 | AA26: 449197.75 | AB26: 423709.27 | AC26: 498037.78 | AD26: =+SUM(R26:AC26) -> 5036736.4 | AE26: 406312.42 | AF26: 415099.46 | AG26: 479919.92 | AH26: 1025325.8 | AI26: 484342.29 | AJ26: 448588.67 | AK26: 506003.71 | AL26: 458226.18 | AM26: 492833.81 | AN26: 418317.08 | AO26: 409100.82 | AP26: 507233.37 | AQ26: =+SUM(AE26:AP26) -> 6051303.5 | AR26: 451320.15 | AS26: 449741.35 | AT26: 491990.72 | AU26: 290044.85 | AV26: 524070.52 | AW26: 449880.37 | AX26: 441153.32 | AY26: 430095.35 | AZ26: 488887.39 | BA26: 525114.51 | BB26: 578955.17 | BC26: 594513.38 | BD26: =+SUM(AR26:BC26) -> 5715767.1 | BE26: 453798.06 | BF26: 511925.56 | BG26: 566403.72 | BH26: 417350.03 | BI26: 537819.84 | BJ26: 542405.12 | BK26: 536733.82 | BL26: 443100.14 | BM26: 443783.94 | BN26: 426756.04 | BO26: 488816.57 | BP26: 509719.57 | BQ26: =+SUM(BE26:BP26) -> 5878612.4 | BR26: 502592.69 | BS26: 465724.23 | BT26: 577894.48
A27: 2110150 | B27: CECOS PLANTA | C27: SULFUROS | D27: ESPESAMIENTO Y BOMBEO DE RELAVES | E27: 0 | F27: 40859.836 | G27: 339557.06 | H27: 385637.23 | I27: 425329.59 | J27: 409765.24 | K27: 447486.43 | L27: 414616.17 | M27: 581836.22 | N27: 511389.98 | O27: 354955.04 | P27: 336267.8 | Q27: =+SUM(E27:P27) -> 4247700.6 | R27: 413124.39 | S27: 377892.5 | T27: 363621.1 | U27: 427093.5 | V27: 387268 | W27: 401798 | X27: 376736 | Y27: 451653 | Z27: 413639 | AA27: 386453.5 | AB27: 359299.5 | AC27: 464982.5 | AD27: =+SUM(R27:AC27) -> 4823561 | AE27: 389666.43 | AF27: 364291.31 | AG27: 395023.52 | AH27: 335107.26 | AI27: 439902.73 | AJ27: 382289.59 | AK27: 403369.88 | AL27: 341112.25 | AM27: 352191.75 | AN27: 394254.2 | AO27: 323076.56 | AP27: 390257.22 | AQ27: =+SUM(AE27:AP27) -> 4510542.7 | AR27: 426072.74 | AS27: 480256.36 | AT27: 514072.59 | AU27: 250075.79 | AV27: 413901.3 | AW27: 424818.78 | AX27: 350628.82 | AY27: 461582 | AZ27: 359379.02 | BA27: 411699.28 | BB27: 323632.23 | BC27: 323152.67 | BD27: =+SUM(AR27:BC27) -> 4739271.6 | BE27: 271574.3 | BF27: 358573.12 | BG27: 378917.64 | BH27: 349683.58 | BI27: 411505.35 | BJ27: 421087.17 | BK27: 427275.52 | BL27: 365200.89 | BM27: 435640.68 | BN27: 374016.95 | BO27: 439943.73 | BP27: 407157.48 | BQ27: =+SUM(BE27:BP27) -> 4640576.4 | BR27: 344633.08 | BS27: 344387.13 | BT27: 336007.52
C28: INFRAESTRUCTURA | E28: =+SUM(E29:E30) -> 607498.68 | F28: =+SUM(F29:F30) -> 1064313.2 | G28: =+SUM(G29:G30) -> 1647764.9 | H28: =+SUM(H29:H30) -> 1460546 | I28: =+SUM(I29:I30) -> 1610875.1 | J28: =+SUM(J29:J30) -> 1551927.4 | K28: =+SUM(K29:K30) -> 1694791 | L28: =+SUM(L29:L30) -> 1570299.6 | ... P28: =+SUM(P29:P30) -> 3053561.7 | Q28: =+SUM(E28:P28) -> 22552389 | R28: =+SUM(R29:R30) -> 3560275.7 | S28: =+SUM(S29:S30) -> 3020363.4 | T28: =+SUM(T29:T30) -> 3335121.8 | U28: =+SUM(U29:U30) -> 3659112.6 | V28: =+SUM(V29:V30) -> 3611308.2 | W28: =+SUM(W29:W30) -> 3770863.3 | X28: =+SUM(X29:X30) -> 3466619.9 | Y28: =+SUM(Y29:Y30) -> 3670241.5 | ... AP28: =+SUM(AP29:AP30) -> 4470521.7 | AQ28: =+SUM(AE28:AP28) -> 51037485 | AR28: =+SUM(AR29:AR30) -> 4465109 | AS28: =+SUM(AS29:AS30) -> 4370292.6 | AT28: =+SUM(AT29:AT30) -> 4765883.4 | AU28: =+SUM(AU29:AU30) -> 3249872.1 | AV28: =+SUM(AV29:AV30) -> 4608801 | AW28: =+SUM(AW29:AW30) -> 4270987.7 | AX28: =+SUM(AX29:AX30) -> 4050934.2 | AY28: =+SUM(AY29:AY30) -> 4346420.4 | ... BC28: =+SUM(BC29:BC30) -> 4397553.1 | BD28: =+SUM(AR28:BC28) -> 51451704 | BE28: =+SUM(BE29:BE30) -> 4137071 | BF28: =+SUM(BF29:BF30) -> 3940153.8 | BG28: =+SUM(BG29:BG30) -> 4685889.6 | BH28: =+SUM(BH29:BH30) -> 4235465.5 | BI28: =+SUM(BI29:BI30) -> 4494460.4 | BJ28: =+SUM(BJ29:BJ30) -> 4454419.4 | BK28: =+SUM(BK29:BK30) -> 4660321.1 | BL28: =+SUM(BL29:BL30) -> 4346503 | ... BP28: =+SUM(BP29:BP30) -> 4687223.7 | BQ28: =+SUM(BE28:BP28) -> 53058981 | BR28: =+SUM(BR29:BR30) -> 4420180.6 | BS28: =+SUM(BS29:BS30) -> 4378780.2 | BT28: =+SUM(BT29:BT30) -> 4907072.2
A29: 2130111 | B29: CECOS PUERTO | C29: INFRAESTRUCTURA | D29: AGUA DE MAR | E29: 76314.618 | F29: 504132.4 | G29: 363002.29 | H29: 524395.75 | I29: 578370.05 | J29: 557205.4 | K29: 608499.29 | L29: 563801.77 | M29: 612660.31 | N29: 608822.83 | O29: 602882.44 | P29: 567553.63 | Q29: =+SUM(E29:P29) -> 6167640.8 | R29: 599551.08 | S29: 556093.04 | T29: 595126.28 | U29: 651704.09 | V29: 646043.54 | W29: 647559 | X29: 609239.52 | Y29: 606694.84 | Z29: 609542.2 | AA29: 626884.97 | AB29: 574861.8 | AC29: 642630.82 | AD29: =+SUM(R29:AC29) -> 7365931.2 | AE29: 553384.82 | AF29: 505646.95 | AG29: 598403.03 | AH29: 760879.9 | AI29: 601255.67 | AJ29: 576168.07 | AK29: 783560.69 | AL29: 764180.27 | AM29: 786234.1 | AN29: 753283.54 | AO29: 680983.73 | AP29: 768734.09 | AQ29: =+SUM(AE29:AP29) -> 8132714.9 | AR29: 721565.75 | AS29: 706059.13 | AT29: 744185.73 | AU29: 600632.93 | AV29: 730383.37 | AW29: 732252.41 | AX29: 684603.41 | AY29: 700928.38 | AZ29: 689775.61 | BA29: 672020.68 | BB29: 682255.23 | BC29: 705122.62 | BD29: =+SUM(AR29:BC29) -> 8369785.3 | BE29: 658309.78 | BF29: 617485.33 | BG29: 723103.05 | BH29: 682111.51 | BI29: 733170.68 | BJ29: 730346.34 | BK29: 764392.62 | BL29: 756266.6 | BM29: 772485.73 | BN29: 736004.67 | BO29: 746596.6 | BP29: 753823.39 | BQ29: =+SUM(BE29:BP29) -> 8674096.3 | BR29: 756490.43 | BS29: 699782.94 | BT29: 782610.17
A30: 2130140 | B30: CECOS PUERTO | C30: INFRAESTRUCTURA | D30: ESTACIÓN DE BOMBEO DE AGUA DE MAR | E30: 531184.06 | F30: 560180.79 | G30: 1284762.6 | H30: 936150.23 | I30: 1032505 | J30: 994721.96 | K30: 1086291.7 | L30: 1006497.8 | M30: 1170332.5 | N30: 2946695.2 | O30: 2349417.9 | P30: 2486008 | Q30: =+SUM(E30:P30) -> 16384748 | R30: 2960724.7 | S30: 2464270.3 | T30: 2739995.6 | U30: 3007408.5 | V30: 2965264.7 | W30: 3123304.3 | X30: 2857380.4 | Y30: 3063546.7 | Z30: 2885291.5 | AA30: 2989330.7 | AB30: 3033716.7 | AC30: 3926560 | AD30: =+SUM(R30:AC30) -> 36016794 | AE30: 3299514.9 | AF30: 3193872.1 | AG30: 3878748.7 | AH30: 3455851.3 | AI30: 3545605.4 | AJ30: 3274669.4 | AK30: 3680561.8 | AL30: 3646384.1 | AM30: 4080335.7 | AN30: 3768111.5 | AO30: 3379328.1 | AP30: 3701787.6 | AQ30: =+SUM(AE30:AP30) -> 42904771 | AR30: 3743543.3 | AS30: 3664233.4 | AT30: 4021697.6 | AU30: 2649239.1 | AV30: 3878417.7 | AW30: 3538735.2 | AX30: 3366330.8 | AY30: 3645492 | AZ30: 3537225.5 | BA30: 3688951.8 | BB30: 3655622.1 | BC30: 3692430.5 | BD30: =+SUM(AR30:BC30) -> 43081919 | BE30: 3478761.3 | BF30: 3322668.5 | BG30: 3962786.5 | BH30: 3553354 | BI30: 3761289.7 | BJ30: 3724073.1 | BK30: 3895928.5 | BL30: 3590236.4 | BM30: 3848481.3 | BN30: 3584103.6 | BO30: 3729802 | BP30: 3933400.3 | BQ30: =+SUM(BE30:BP30) -> 44384885 | BR30: 3663690.2 | BS30: 3678997.3 | BT30: 4124462.1
C31: OXIDOS | E31: =+SUM(E33:E43) -> 477826.18 | F31: =+SUM(F33:F43) -> 249446.84 | G31: =+SUM(G33:G43) -> 950990.56 | H31: =+SUM(H33:H43) -> 5416189 | I31: =+SUM(I33:I43) -> 5973659.3 | J31: =+SUM(J33:J43) -> 5755062.5 | K31: =+SUM(K33:K43) -> 6284848.3 | L31: =+SUM(L33:L43) -> 5823192.7 | ... P31: =+SUM(P33:P43) -> 7017391.8 | Q31: =+SUM(E31:P31) -> 52909393 | R31: =+SUM(R33:R43) -> 7757675.2 | S31: =+SUM(S33:S43) -> 6489577.8 | T31: =+SUM(T33:T43) -> 5720687.6 | U31: =+SUM(U33:U43) -> 7173288.7 | V31: =+SUM(V33:V43) -> 8505686.2 | W31: =+SUM(W33:W43) -> 8347080.4 | X31: =+SUM(X33:X43) -> 9507665 | Y31: =+SUM(Y33:Y43) -> 8602880.7 | ... AC31: =+SUM(AC33:AC43) -> 11274383 | AD31: =+SUM(AD43+AD32) -> 1.0429083e+08 | AE31: =+SUM(AE33:AE43) -> 12256189 | AF31: =+SUM(AF33:AF43) -> 9704016.3 | AG31: =+SUM(AG33:AG43) -> 11461597 | AH31: =+SUM(AH33:AH43) -> 10642807 | AI31: =+SUM(AI33:AI43) -> 10637880 | AJ31: =+SUM(AJ33:AJ43) -> 9360100.8 | AK31: =+SUM(AK33:AK43) -> 12516885 | AL31: =+SUM(AL33:AL43) -> 11380104 | ... AP31: =+SUM(AP33:AP43) -> 11927578 | AQ31: =+SUM(AE31:AP31) -> 1.3509034e+08 | AR31: =+SUM(AR33:AR43) -> 10351249 | AS31: =+SUM(AS33:AS43) -> 10943335 | AT31: =+SUM(AT33:AT43) -> 8591807.2 | AU31: =+SUM(AU33:AU43) -> 10583796 | AV31: =+SUM(AV33:AV43) -> 9605401.4 | AW31: =+SUM(AW33:AW43) -> 9885141.2 | AX31: =+SUM(AX33:AX43) -> 10700862 | AY31: =+SUM(AY33:AY43) -> 9686268.3 | ... BC31: =+SUM(BC33:BC43) -> 10976428 | BD31: =+SUM(AR31:BC31) -> 1.2133071e+08 | BE31: =+SUM(BE43+BE32) -> 10982476 | BF31: =+SUM(BF43+BF32) -> 7605282.5 | BG31: =+SUM(BG43+BG32) -> 10695211 | BH31: =+SUM(BH43+BH32) -> 10913603 | BI31: =+SUM(BI43+BI32) -> 10435605 | BJ31: =+SUM(BJ43+BJ32) -> 10924833 | BK31: =+SUM(BK43+BK32) -> 12002118 | BL31: =+SUM(BL43+BL32) -> 12512224 | ... BP31: =+SUM(BP43+BP32) -> 12709810 | BQ31: =+SUM(BE31:BP31) -> 1.3557663e+08 | BR31: =+SUM(BR43+BR32) -> 12608613 | BS31: =+SUM(BS43+BS32) -> 11385966 | BT31: =+SUM(BT43+BT32) -> 10847640
R32: =+SUM(R33:R42) -> 4428978.5 | S32: =+SUM(S33:S42) -> 3733190.7 | T32: =+SUM(T33:T42) -> 3387067.4 | U32: =+SUM(U33:U42) -> 3812126.1 | V32: =+SUM(V33:V42) -> 4501970.3 | W32: =+SUM(W33:W42) -> 4328094.7 | X32: =+SUM(X33:X42) -> 4656056.8 | Y32: =+SUM(Y33:Y42) -> 3806841 | ... AP32: =+SUM(AP33:AP42) -> 5815426 | AQ32: =+SUM(AE32:AP32) -> 65120136 | AR32: =+SUM(AR33:AR42) -> 5231112.3 | AS32: =+SUM(AS33:AS42) -> 5578318.4 | AT32: =+SUM(AT33:AT42) -> 4520146.5 | AU32: =+SUM(AU33:AU42) -> 5537290.2 | AV32: =+SUM(AV33:AV42) -> 5018161.9 | AW32: =+SUM(AW33:AW42) -> 5263802.9 | AX32: =+SUM(AX33:AX42) -> 5437633.5 | AY32: =+SUM(AY33:AY42) -> 4906510.6 | ... BC32: =+SUM(BC33:BC42) -> 5614942.9 | BD32: =+SUM(AR32:BC32) -> 62769703 | BE32: =+SUM(BE33:BE42) -> 5723991.3 | BF32: =+SUM(BF33:BF42) -> 4154023.7 | BG32: =+SUM(BG33:BG42) -> 5489010.1 | BH32: =+SUM(BH33:BH42) -> 5475476.9 | BI32: =+SUM(BI33:BI42) -> 4900151.1 | BJ32: =+SUM(BJ33:BJ42) -> 5357958.3 | BK32: =+SUM(BK33:BK42) -> 5710983.8 | BL32: =+SUM(BL33:BL42) -> 5585659.7 | ... BP32: =+SUM(BP33:BP42) -> 5587174.1 | BQ32: =+SUM(BE32:BP32) -> 64034686 | BR32: =+SUM(BR33:BR42) -> 5777090.1 | BS32: =+SUM(BS33:BS42) -> 5152522.6 | BT32: =+SUM(BT33:BT42) -> 4967566.2
A33: 2120101 | B33: CECOS PLANTA | C33: OXIDOS | D33: CHANCADO PRIMARIO | E33: 90119.478 | F33: 80175.695 | G33: 39932.153 | H33: 22636.32 | I33: 24966.201 | J33: 24052.598 | K33: 26266.774 | L33: 24337.34 | M33: 22934.718 | N33: 117751.45 | O33: 23276.304 | P33: 113488.15 | Q33: =+SUM(E33:P33) -> 609937.17 | R33: 180541.93 | S33: 137071.3 | T33: 168358.11 | U33: 136444.57 | V33: 150800.38 | W33: 234009.45 | X33: 145330.21 | Y33: 141697.6 | Z33: 145499.69 | AA33: 187791.78 | AB33: 167074.74 | AC33: 182253.62 | AD33: =+SUM(R33:AC33) -> 1976873.4 | AE33: 170252.05 | AF33: 151639.73 | AG33: 180876.99 | AH33: 159191.17 | AI33: 158016.56 | AJ33: 130630.3 | AK33: 170332.89 | AL33: 158740.4 | AM33: 180130.23 | AN33: 182145.58 | AO33: 151010.55 | AP33: 174556.67 | AQ33: =+SUM(AE33:AP33) -> 1967523.1 | AR33: 163190.01 | AS33: 163096.34 | AT33: 147649.58 | AU33: 138291.07 | AV33: 147077.13 | AW33: 123569.71 | AX33: 137574.45 | AY33: 164317.38 | AZ33: 156951.85 | BA33: 163730.61 | BB33: 182906.74 | BC33: 199948.2 | BD33: =+SUM(AR33:BC33) -> 1888303.1 | BE33: 186766.95 | BF33: 154452.18 | BG33: 188436 | BH33: 166547.4 | BI33: 155105.89 | BJ33: 157658.15 | BK33: 177130.16 | BL33: 172812.17 | BM33: 177858.77 | BN33: 159030.48 | BO33: 179361.3 | BP33: 175869.99 | BQ33: =+SUM(BE33:BP33) -> 2051029.5 | BR33: 186301.73 | BS33: 172707.11 | BT33: 171363.83
A34: 2120102 | B34: CECOS PLANTA | C34: OXIDOS | D34: ZARANDEO Y CHANCADO SECUNDARIOS | E34: 179425.37 | F34: 67708.458 | G34: 34834.041 | H34: 367284.81 | I34: 405088.21 | J34: 390264.57 | K34: 426190.61 | L34: 394884.64 | M34: 372126.45 | N34: 428315.21 | O34: 581397.02 | P34: 469515.66 | Q34: =+SUM(E34:P34) -> 4117035 | R34: 522372.86 | S34: 436645.68 | T34: 355597.22 | U34: 429789.03 | V34: 533944.76 | W34: 485646.86 | X34: 557503.95 | Y34: 442530.12 | Z34: 562495.27 | AA34: 592620.82 | AB34: 635654.28 | AC34: 628321.29 | AD34: =+SUM(R34:AC34) -> 6183122.2 | AE34: 662690.23 | AF34: 527851.49 | AG34: 660918.24 | AH34: 571982.34 | AI34: 599215.1 | AJ34: 539220.53 | AK34: 731356.39 | AL34: 693684.53 | AM34: 757843.45 | AN34: 669882.95 | AO34: 699123.33 | AP34: 699784.21 | AQ34: =+SUM(AE34:AP34) -> 7813552.8 | AR34: 614176.34 | AS34: 664705.49 | AT34: 513601.06 | AU34: 668785.59 | AV34: 589869.36 | AW34: 631534.78 | AX34: 639107.92 | AY34: 570497.16 | AZ34: 610767.15 | BA34: 571654.1 | BB34: 629818.31 | BC34: 661274.84 | BD34: =+SUM(AR34:BC34) -> 7365792.1 | BE34: 671049.06 | BF34: 468031.12 | BG34: 644169.75 | BH34: 646483.86 | BI34: 556065.26 | BJ34: 632999.64 | BK34: 667168.28 | BL34: 643304.27 | BM34: 650452.02 | BN34: 554709.74 | BO34: 631422.21 | BP34: 627343.34 | BQ34: =+SUM(BE34:BP34) -> 7393198.6 | BR34: 632198.99 | BS34: 556002.67 | BT34: 551152.75
A35: 2120103 | B35: CECOS PLANTA | C35: OXIDOS | D35: ZARANDEO Y CHANCADO TERCIARIOS | E35: 31692.598 | F35: 101562.69 | G35: 63576.182 | H35: 739090.14 | I35: 815162.23 | J35: 785332.5 | K35: 857626.76 | L35: 794629.51 | M35: 748833.01 | N35: 1066570.2 | O35: 1169949.8 | P35: 1878062.6 | Q35: =+SUM(E35:P35) -> 9052088.2 | R35: 2089491.4 | S35: 1746582.7 | T35: 1422388.9 | U35: 1719156.1 | V35: 2135779.1 | W35: 1942587.5 | X35: 2230015.8 | Y35: 1770120.5 | Z35: 2249981.1 | AA35: 2370483.3 | AB35: 2542617.1 | AC35: 2513285.1 | AD35: =+SUM(R35:AC35) -> 24732489 | AE35: 2650760.9 | AF35: 2111406 | AG35: 2643673 | AH35: 2287929.4 | AI35: 2396860.4 | AJ35: 2156882.1 | AK35: 2925425.6 | AL35: 2774738.1 | AM35: 3031373.8 | AN35: 2679531.8 | AO35: 2796493.3 | AP35: 2799136.8 | AQ35: =+SUM(AE35:AP35) -> 31254211 | AR35: 2456705.4 | AS35: 2658822 | AT35: 2054404.2 | AU35: 2675142.4 | AV35: 2359477.4 | AW35: 2526139.1 | AX35: 2556431.7 | AY35: 2281988.6 | AZ35: 2443068.6 | BA35: 2286616.4 | BB35: 2519273.2 | BC35: 2645099.3 | BD35: =+SUM(AR35:BC35) -> 29463168 | BE35: 2684196.3 | BF35: 1872124.5 | BG35: 2576679 | BH35: 2585935.5 | BI35: 2224261.1 | BJ35: 2531998.6 | BK35: 2668673.1 | BL35: 2573217.1 | BM35: 2601808.1 | BN35: 2218839 | BO35: 2525688.8 | BP35: 2509373.4 | BQ35: =+SUM(BE35:BP35) -> 29572794 | BR35: 2528796 | BS35: 2224010.7 | BT35: 2204611
A36: 2120104 | B36: CECOS PLANTA | C36: OXIDOS | D36: PRODUCTO DE MINERAL FINO | E36: 38808.952 | F36: 0 | G36: 298337.33 | H36: 47323.008 | I36: 52193.808 | J36: 50283.848 | K36: 54912.758 | L36: 50879.123 | M36: 47946.832 | N36: 254739.01 | O36: 84341.47 | P36: 130860.57 | Q36: =+SUM(E36:P36) -> 1110626.7 | R36: 161755.85 | S36: 157180.89 | T36: 144308.14 | U36: 150932.24 | V36: 178773.46 | W36: 174253.48 | X36: 202167.63 | Y36: 198078.04 | Z36: 268712.39 | AA36: 304576.01 | AB36: 355877.63 | AC36: 388973.94 | AD36: =+SUM(R36:AC36) -> 2685589.7 | AE36: 482354.42 | AF36: 414667.89 | AG36: 475431.91 | AH36: 462505.6 | AI36: 462542.29 | AJ36: 404760.81 | AK36: 539686.73 | AL36: 403806.68 | AM36: 537289.85 | AN36: 479702.74 | AO36: 457246.86 | AP36: 527814.61 | AQ36: =+SUM(AE36:AP36) -> 5647810.4 | AR36: 476423.94 | AS36: 486762.79 | AT36: 409799.63 | AU36: 470187.44 | AV36: 487653.75 | AW36: 488164.58 | AX36: 504554.81 | AY36: 460534.45 | AZ36: 484415.05 | BA36: 504863 | BB36: 479936.11 | BC36: 475069.5 | BD36: =+SUM(AR36:BC36) -> 5728365 | BE36: 480032.82 | BF36: 366157.53 | BG36: 463859.18 | BH36: 485924.96 | BI36: 440112.88 | BJ36: 443761.95 | BK36: 494745.73 | BL36: 499784.84 | BM36: 473464.98 | BN36: 417049.61 | BO36: 517191.5 | BP36: 525871.44 | BQ36: =+SUM(BE36:BP36) -> 5607957.4 | BR36: 569176.87 | BS36: 505481.36 | BT36: 461067.07
A37: 2120110 | B37: CECOS PLANTA | C37: OXIDOS | D37: PRETATAMIENTO VATEAS Y POZAS | E37: 21845.551 | F37: 0 | G37: 198891.55 | H37: 141919.24 | I37: 156526.51 | J37: 150798.64 | K37: 164680.5 | L37: 152583.84 | M37: 143790.05 | N37: 255896.63 | O37: 279276.32 | P37: 82171.552 | Q37: =+SUM(E37:P37) -> 1748380.4 | R37: 89817.363 | S37: 78310.216 | T37: 66666.469 | U37: 77052.535 | V37: 89471.939 | W37: 82937.128 | X37: 95371.698 | Y37: 78476.232 | Z37: 97700.264 | AA37: 102378.73 | AB37: 110626.29 | AC37: 118698.2 | AD37: =+SUM(R37:AC37) -> 1087507.1 | AE37: 116129.06 | AF37: 97938.277 | AG37: 118810.73 | AH37: 174884.69 | AI37: 106904.84 | AJ37: 98000.991 | AK37: 127044.58 | AL37: 120254.14 | AM37: 129994.4 | AN37: 120265.73 | AO37: 126946.14 | AP37: 128155.95 | AQ37: =+SUM(AE37:AP37) -> 1465329.5 | AR37: 118630.01 | AS37: 131650.57 | AT37: 105843.47 | AU37: 132921.42 | AV37: 119050.09 | AW37: 119640.1 | AX37: 125281.96 | AY37: 105986.21 | AZ37: 117189.26 | BA37: 110581.75 | BB37: 120860.56 | BC37: 121949.59 | BD37: =+SUM(AR37:BC37) -> 1429585 | BE37: 125478.11 | BF37: 93980.72 | BG37: 123145.51 | BH37: 123681.59 | BI37: 115037.64 | BJ37: 126658.54 | BK37: 129202.82 | BL37: 129266.43 | BM37: 126104.76 | BN37: 112477.11 | BO37: 123367.52 | BP37: 124433.75 | BQ37: =+SUM(BE37:BP37) -> 1452834.5 | BR37: 127281.91 | BS37: 115214.3 | BT37: 109160.54
A38: 2120113 | B38: CECOS PLANTA | C38: OXIDOS | D38: DISPOSICIÓN DE RIPIOS | E38: 48490.503 | F38: 0 | G38: 6311.386 | H38: 56155.704 | I38: 61935.623 | J38: 59669.175 | K38: 65162.057 | L38: 60375.557 | M38: 56895.962 | N38: 101255.16 | O38: 142026.52 | P38: 184505.51 | Q38: =+SUM(E38:P38) -> 842783.16 | R38: 213682.19 | S38: 180058.16 | T38: 158982.37 | U38: 171269.72 | V38: 208420.67 | W38: 203628.15 | X38: 213742.83 | Y38: 187073.24 | Z38: 214211.26 | AA38: 239312.07 | AB38: 261010.23 | AC38: 251276.34 | AD38: =+SUM(R38:AC38) -> 2502667.2 | AE38: 301576.57 | AF38: 242179.76 | AG38: 289381.63 | AH38: 219452.47 | AI38: 224877.08 | AJ38: 191629.55 | AK38: 248190.51 | AL38: 232746.53 | AM38: 254150.4 | AN38: 247288.55 | AO38: 231204.65 | AP38: 250640.81 | AQ38: =+SUM(AE38:AP38) -> 2933318.5 | AR38: 248967.75 | AS38: 261112.05 | AT38: 210465.78 | AU38: 243939.42 | AV38: 216617.95 | AW38: 237698.35 | AX38: 250489.43 | AY38: 228953.97 | AZ38: 247147.1 | BA38: 233712.02 | BB38: 254634.33 | BC38: 249320.75 | BD38: =+SUM(AR38:BC38) -> 2883058.9 | BE38: 264542.65 | BF38: 200228.21 | BG38: 253899.88 | BH38: 257980.1 | BI38: 246804.9 | BJ38: 244827.33 | BK38: 264798.93 | BL38: 260405.27 | BM38: 257298.96 | BN38: 224529.07 | BO38: 252039.3 | BP38: 261881.34 | BQ38: =+SUM(BE38:BP38) -> 2989235.9 | BR38: 273260.23 | BS38: 252642 | BT38: 240799.73
A39: 2120120 | B39: CECOS PLANTA | C39: OXIDOS | D39: ALIMENTADOR DE BATEAS | E39: 0 | F39: 0 | G39: 11725.173 | H39: 138733.25 | I39: 153012.6 | J39: 147413.32 | K39: 160983.54 | L39: 149158.44 | M39: 140562.06 | N39: 250151.92 | O39: 147744.7 | P39: 86805.229 | Q39: =+SUM(E39:P39) -> 1386290.2 | R39: 105696.12 | S39: 90804.752 | T39: 83279.575 | U39: 84121.297 | V39: 101034.98 | W39: 98939.922 | X39: 101854.96 | Y39: 93819.483 | Z39: 106765.08 | AA39: 119286.15 | AB39: 134459.32 | AC39: 129026.52 | AD39: =+SUM(R39:AC39) -> 1249088.2 | AE39: 147101.55 | AF39: 121075.09 | AG39: 153032.63 | AH39: 104596.82 | AI39: 135829.53 | AJ39: 115092.25 | AK39: 145645.16 | AL39: 211912.63 | AM39: 149739.18 | AN39: 142184.68 | AO39: 135733.75 | AP39: 146188.99 | AQ39: =+SUM(AE39:AP39) -> 1708132.3 | AR39: 139445.31 | AS39: 147037.11 | AT39: 117418.75 | AU39: 140348.61 | AV39: 126804.96 | AW39: 136037.23 | AX39: 141695.51 | AY39: 130054.65 | AZ39: 136250.24 | BA39: 130026.6 | BB39: 148399.67 | BC39: 144605.68 | BD39: =+SUM(AR39:BC39) -> 1638124.3 | BE39: 152188.42 | BF39: 115403.88 | BG39: 141103.08 | BH39: 146480.73 | BI39: 140391.92 | BJ39: 140842.53 | BK39: 155056.78 | BL39: 150956.92 | BM39: 151301.82 | BN39: 128003.64 | BO39: 145728.07 | BP39: 152033.2 | BQ39: =+SUM(BE39:BP39) -> 1719491 | BR39: 156158.82 | BS39: 143658.78 | BT39: 132990.07
A40: 2120123 | B40: CECOS PLANTA | C40: OXIDOS | D40: VAT LEACHING | E40: 4137.4149 | F40: 0 | G40: 50142.031 | H40: 283921.99 | I40: 313145.13 | J40: 301686.96 | K40: 329458.94 | L40: 305258.42 | M40: 287665.61 | N40: 511945.43 | O40: 243897.63 | P40: 303371.01 | Q40: =+SUM(E40:P40) -> 2934630.6 | R40: 354928.79 | S40: 322358.37 | T40: 300462.79 | U40: 322804.49 | V40: 409143.21 | W40: 381271.1 | X40: 389401.25 | Y40: 287870.93 | Z40: 343627.1 | AA40: 408448.86 | AB40: 461295.13 | AC40: 460248.59 | AD40: =+SUM(R40:AC40) -> 4441860.6 | AE40: 513069.58 | AF40: 428198.91 | AG40: 488854.02 | AH40: 425961.01 | AI40: 449833.14 | AJ40: 407662.39 | AK40: 545799.12 | AL40: 541883.68 | AM40: 535437.49 | AN40: 506130 | AO40: 490944.24 | AP40: 538541.23 | AQ40: =+SUM(AE40:AP40) -> 5872314.8 | AR40: 488236.94 | AS40: 542945.32 | AT40: 492406.03 | AU40: 539633.22 | AV40: 487054.33 | AW40: 506838.95 | AX40: 534796.65 | AY40: 466579.54 | AZ40: 505399.87 | BA40: 507668.27 | BB40: 527346.14 | BC40: 571210.71 | BD40: =+SUM(AR40:BC40) -> 6170116 | BE40: 610751.85 | BF40: 447695.8 | BG40: 554524.24 | BH40: 547575.2 | BI40: 502731.83 | BJ40: 532368.87 | BK40: 581682.16 | BL40: 556785.04 | BM40: 562834.51 | BN40: 495067.64 | BO40: 583700.41 | BP40: 595621.15 | BQ40: =+SUM(BE40:BP40) -> 6571338.7 | BR40: 664804.02 | BS40: 602869.28 | BT40: 550784.21
...

Sheet Graficas
B1: REPORTE DE PALAS ELÉCTRICAS MINA | N1: REPORTE DE CONSUMO ENERGÍA SULFUROS | Z1: REPORTE DE CONSUMO ENERGÍA INFRAESTRUCTURA
K3: Lec. Anterior | L3: =+'DETALLE ENERGIA Y FACTURA'!BA14 -> 2544286.8 | W3: Lec. Anterior | X3: =+'DETALLE ENERGIA Y FACTURA'!BA19 -> 13830338 | AI3: Lec. Anterior | AJ3: =+'DETALLE ENERGIA Y FACTURA'!BA28 -> 4360972.5
K4: Lec. Actual | L4: =+'DETALLE ENERGIA Y FACTURA'!BN14 -> 2780572.3 | W4: Lec. Actual | X4: =+'DETALLE ENERGIA Y FACTURA'!BN19 -> 12349020 | AI4: Lec. Actual | AJ4: =+'DETALLE ENERGIA Y FACTURA'!BN28 -> 4320108.3
K5: Var | L5: =+L4/L3-1 -> 0.092869017 | W5: Var | X5: =+X4/X3-1 -> -0.10710643 | AI5: Var | AJ5: =+AJ4/AJ3-1 -> -0.0093704488
W8: Ratio PB-25 | X8: 22.508721 | AI8: Ratio PB-25 | AJ8: 6.8743972
W9: Ratio Real | X9: =+'DETALLE ENERGIA Y FACTURA'!BN60 -> 23.388295 | AI9: Ratio Real | AJ9: =+'DETALLE ENERGIA Y FACTURA'!BN62 -> 6.9011314
W10: Var | X10: =+X9/X8-1 -> 0.039077021 | AI10: Var | AJ10: =+AJ9/AJ8-1 -> 0.0038889479
B23: REPORTE DE PERFORADORAS ELÉCTRICAS MINA | N23: REPORTE DE CONSUMO ENERGÍA ÓXIDOS | Z23: REPORTE REAL TONELDAS Y BOMBEO H2O - 2025
AA24: Mes | AB24: Mov Tn Pry | AC24: Mov Tn Real | AD24: Sul Pry | AE24: Sul Real | AF24: Oxi Pry | AG24: Oxi Real | AH24: H2O Pry | AI24: H2O Real
K25: Lec. Anterior | L25: =+'DETALLE ENERGIA Y FACTURA'!BA15 -> 636071.71 | W25: Lec. Anterior | X25: =+'DETALLE ENERGIA Y FACTURA'!BA31 -> 9406805.4 | AA25: Ene | AB25: 9583 | AC25: =+'DETALLE ENERGIA Y FACTURA'!BE54/1000 -> 9255 | AD25: 504 | AE25: =+'DETALLE ENERGIA Y FACTURA'!BE55/1000 -> 507 | AF25: 958 | AG25: =+'DETALLE ENERGIA Y FACTURA'!BE56/1000 -> 989 | AH25: 615 | AI25: =+'DETALLE ENERGIA Y FACTURA'!BE57 -> 595000
K26: Lec. Actual | L26: =+'DETALLE ENERGIA Y FACTURA'!BN15 -> 665381.59 | W26: Lec. Actual | X26: =+'DETALLE ENERGIA Y FACTURA'!BN31 -> 11141256 | AA26: Feb | AB26: 8949 | AC26: =+'DETALLE ENERGIA Y FACTURA'!BF54/1000 -> 8341 | AD26: 547 | AE26: =+'DETALLE ENERGIA Y FACTURA'!BF55/1000 -> 568 | AF26: 753 | AG26: =+'DETALLE ENERGIA Y FACTURA'!BF56/1000 -> 664 | AH26: 586 | AI26: =+'DETALLE ENERGIA Y FACTURA'!BF57 -> 573000
K27: Var | L27: =+L26/L25-1 -> 0.046079518 | W27: Var | X27: =+X26/X25-1 -> 0.18438258 | AA27: Mar | AB27: 9979 | AC27: =+'DETALLE ENERGIA Y FACTURA'!BG54/1000 -> 9732 | AD27: 618 | AE27: =+'DETALLE ENERGIA Y FACTURA'!BG55/1000 -> 611 | AF27: 957 | AG27: =+'DETALLE ENERGIA Y FACTURA'!BG56/1000 -> 958 | AH27: 686 | AI27: =+'DETALLE ENERGIA Y FACTURA'!BG57 -> 667000
AA28: Abr | AB28: 8085 | AC28: =+'DETALLE ENERGIA Y FACTURA'!BH54/1000 -> 9565 | AD28: 495 | AE28: =+'DETALLE ENERGIA Y FACTURA'!BH55/1000 -> 503 | AF28: 929 | AG28: =+'DETALLE ENERGIA Y FACTURA'!BH56/1000 -> 984 | AH28: 600 | AI28: =+'DETALLE ENERGIA Y FACTURA'!BH57 -> 597000
AA29: May | AB29: 9704 | AC29: =+'DETALLE ENERGIA Y FACTURA'!BI54/1000 -> 10116 | AD29: 623 | AE29: =+'DETALLE ENERGIA Y FACTURA'!BI55/1000 -> 604 | AF29: 911 | AG29: =+'DETALLE ENERGIA Y FACTURA'!BI56/1000 -> 863 | AH29: 678 | AI29: =+'DETALLE ENERGIA Y FACTURA'!BI57 -> 648000
W30: Ratio PB-25 | X30: 13.658635 | AA30: Jun | AB30: 9318 | AC30: =+'DETALLE ENERGIA Y FACTURA'!BJ54/1000 -> 9124 | AD30: 610 | AE30: =+'DETALLE ENERGIA Y FACTURA'!BJ55/1000 -> 579 | AF30: 922 | AG30: =+'DETALLE ENERGIA Y FACTURA'!BJ56/1000 -> 972 | AH30: 669 | AI30: =+'DETALLE ENERGIA Y FACTURA'!BJ57 -> 635000
W31: Ratio Real | X31: =+'DETALLE ENERGIA Y FACTURA'!BN61 -> 12.954949 | AA31: Jul | AC31: =+'DETALLE ENERGIA Y FACTURA'!BK54/1000 -> 9699 | AE31: =+'DETALLE ENERGIA Y FACTURA'!BK55/1000 -> 612 | AG31: =+'DETALLE ENERGIA Y FACTURA'!BK56/1000 -> 1039 | AI31: =+'DETALLE ENERGIA Y FACTURA'!BK57 -> 666000
W32: Var | X32: =+X31/X30-1 -> -0.051519462 | AA32: Ago
AA33: Set
AA34: Oct
AA35: Nov
AA36: Dic
AB37: =SUM(AB25:AB36) -> 55618 | AC37: =SUM(AC25:AC36) -> 65832 | AD37: =SUM(AD25:AD36) -> 3397 | AE37: =SUM(AE25:AE36) -> 3984 | AF37: =SUM(AF25:AF36) -> 5430 | AG37: =SUM(AG25:AG36) -> 6469 | AH37: =SUM(AH25:AH36) -> 3834 | AI37: =SUM(AI25:AI36) -> 4381000
AC38: =+AC37/AB37-1 -> 0.18364558 | AE38: =+AE37/AD37-1 -> 0.17279953 | AG38: =+AG37/AF37-1 -> 0.19134438 | AI38: =+AI37/AH37-1 -> 1141.6708

Sheet XLSTAT_20221004_132937_1_HID
A1: 1 | C1: =1227.323+(A1-1)*23.5838260869565 -> 1227.323 | D1: =-109437.657186102+1867.1220958413*C1-313318.788176791*(0.111111111111111+(C1-1989.99988888889)^2/1722930.22013289)^0.5 -> 1972242.8 | E1: 1 | G1: =1227.323+(E1-1)*23.5838260869565 -> 1227.323 | H1: =-109437.657186102+1867.1220958413*G1+313318.788176791*(0.111111111111111+(G1-1989.99988888889)^2/1722930.22013289)^0.5 -> 2392005.7 | I1: 1 | K1: =1227.323+(I1-1)*16.4372121212121 -> 1227.323 | L1: =-109437.657186102+1867.1220958413*K1-313318.788176791*(1.11111111111111+(K1-1989.99988888889)^2/1722930.22013289)^0.5 -> 1805005.1 | M1: 1 | O1: =1227.323+(M1-1)*16.4372121212121 -> 1227.323 | P1: =-109437.657186102+1867.1220958413*O1+313318.788176791*(1.11111111111111+(O1-1989.99988888889)^2/1722930.22013289)^0.5 -> 2559243.4 | Q1: 1 | S1: =2334041.13047858+(Q1-1)*52560.5747131752 -> 2334041.1 | T1: =0+1*S1-313318.788176791*(1.11111111111111+(S1-3606135.10608007)^2/6006384435772.58)^0.5 -> 1965904.5 | U1: 1 | W1: =1948255.2487191+(U1-1)*58151.6744488198 -> 1948255.2 | X1: =0+1*W1+313318.788176791*(1.11111111111111+(W1-3606135.10608007)^2/6006384435772.58)^0.5 -> 2340682.3
A2: 2 | C2: =1227.323+(A2-1)*23.5838260869565 -> 1250.9068 | D2: =-109437.657186102+1867.1220958413*C2-313318.788176791*(0.111111111111111+(C2-1989.99988888889)^2/1722930.22013289)^0.5 -> 2021140.5 | E2: 2 | G2: =1227.323+(E2-1)*23.5838260869565 -> 1250.9068 | H2: =-109437.657186102+1867.1220958413*G2+313318.788176791*(0.111111111111111+(G2-1989.99988888889)^2/1722930.22013289)^0.5 -> 2431175.7 | I2: 2 | K2: =1227.323+(I2-1)*16.4372121212121 -> 1243.7602 | L2: =-109437.657186102+1867.1220958413*K2-313318.788176791*(1.11111111111111+(K2-1989.99988888889)^2/1722930.22013289)^0.5 -> 1837573.7 | M2: 2 | O2: =1227.323+(M2-1)*16.4372121212121 -> 1243.7602 | P2: =-109437.657186102+1867.1220958413*O2+313318.788176791*(1.11111111111111+(O2-1989.99988888889)^2/1722930.22013289)^0.5 -> 2588055.4 | Q2: 2 | S2: =2334041.13047858+(Q2-1)*52560.5747131752 -> 2386601.7 | T2: =0+1*S2-313318.788176791*(1.11111111111111+(S2-3606135.10608007)^2/6006384435772.58)^0.5 -> 2021383.7 | U2: 2 | W2: =1948255.2487191+(U2-1)*58151.6744488198 -> 2006406.9 | X2: =0+1*W2+313318.788176791*(1.11111111111111+(W2-3606135.10608007)^2/6006384435772.58)^0.5 -> 2394869.1
